Traceback (most recent call last):
  File "/home/jmcgrath/miniconda3/envs/ai-test-py312/lib/python3.12/site-packages/huggingface_hub/utils/_http.py", line 409, in hf_raise_for_status
    response.raise_for_status()
  File "/home/jmcgrath/miniconda3/envs/ai-test-py312/lib/python3.12/site-packages/requests/models.py", line 1026, in raise_for_status
    raise HTTPError(http_error_msg, response=self)
requests.exceptions.HTTPError: 401 Client Error: Unauthorized for url: https://huggingface.co/meta-llama/Llama-3.3-70B-Instruct/resolve/main/config.json

The above exception was the direct cause of the following exception:

Traceback (most recent call last):
  File "/home/jmcgrath/miniconda3/envs/ai-test-py312/lib/python3.12/site-packages/transformers/utils/hub.py", line 470, in cached_files
    hf_hub_download(
  File "/home/jmcgrath/miniconda3/envs/ai-test-py312/lib/python3.12/site-packages/huggingface_hub/utils/_validators.py", line 114, in _inner_fn
    return fn(*args, **kwargs)
           ^^^^^^^^^^^^^^^^^^^
  File "/home/jmcgrath/miniconda3/envs/ai-test-py312/lib/python3.12/site-packages/huggingface_hub/file_download.py", line 1008, in hf_hub_download
    return _hf_hub_download_to_cache_dir(
           ^^^^^^^^^^^^^^^^^^^^^^^^^^^^^^
  File "/home/jmcgrath/miniconda3/envs/ai-test-py312/lib/python3.12/site-packages/huggingface_hub/file_download.py", line 1115, in _hf_hub_download_to_cache_dir
    _raise_on_head_call_error(head_call_error, force_download, local_files_only)
  File "/home/jmcgrath/miniconda3/envs/ai-test-py312/lib/python3.12/site-packages/huggingface_hub/file_download.py", line 1645, in _raise_on_head_call_error
    raise head_call_error
  File "/home/jmcgrath/miniconda3/envs/ai-test-py312/lib/python3.12/site-packages/huggingface_hub/file_download.py", line 1533, in _get_metadata_or_catch_error
    metadata = get_hf_file_metadata(
               ^^^^^^^^^^^^^^^^^^^^^
  File "/home/jmcgrath/miniconda3/envs/ai-test-py312/lib/python3.12/site-packages/huggingface_hub/utils/_validators.py", line 114, in _inner_fn
    return fn(*args, **kwargs)
           ^^^^^^^^^^^^^^^^^^^
  File "/home/jmcgrath/miniconda3/envs/ai-test-py312/lib/python3.12/site-packages/huggingface_hub/file_download.py", line 1450, in get_hf_file_metadata
    r = _request_wrapper(
        ^^^^^^^^^^^^^^^^^
  File "/home/jmcgrath/miniconda3/envs/ai-test-py312/lib/python3.12/site-packages/huggingface_hub/file_download.py", line 286, in _request_wrapper
    response = _request_wrapper(
               ^^^^^^^^^^^^^^^^^
  File "/home/jmcgrath/miniconda3/envs/ai-test-py312/lib/python3.12/site-packages/huggingface_hub/file_download.py", line 310, in _request_wrapper
    hf_raise_for_status(response)
  File "/home/jmcgrath/miniconda3/envs/ai-test-py312/lib/python3.12/site-packages/huggingface_hub/utils/_http.py", line 426, in hf_raise_for_status
    raise _format(GatedRepoError, message, response) from e
huggingface_hub.errors.GatedRepoError: 401 Client Error. (Request ID: Root=1-687245c2-32518b280d6d60a15e8d0bac;03c95e9c-8acd-4b2a-8c6d-6a3639ee9671)

Cannot access gated repo for url https://huggingface.co/meta-llama/Llama-3.3-70B-Instruct/resolve/main/config.json.
Access to model meta-llama/Llama-3.3-70B-Instruct is restricted. You must have access to it and be authenticated to access it. Please log in.

The above exception was the direct cause of the following exception:

Traceback (most recent call last):
  File "/home/jmcgrath/Model-RPG/eval.py", line 89, in <module>
    main()
  File "/home/jmcgrath/Model-RPG/eval.py", line 27, in main
    tokenizer = AutoTokenizer.from_pretrained(judge_model)
                ^^^^^^^^^^^^^^^^^^^^^^^^^^^^^^^^^^^^^^^^^^
  File "/home/jmcgrath/miniconda3/envs/ai-test-py312/lib/python3.12/site-packages/transformers/models/auto/tokenization_auto.py", line 1002, in from_pretrained
    config = AutoConfig.from_pretrained(
             ^^^^^^^^^^^^^^^^^^^^^^^^^^^
  File "/home/jmcgrath/miniconda3/envs/ai-test-py312/lib/python3.12/site-packages/transformers/models/auto/configuration_auto.py", line 1197, in from_pretrained
    config_dict, unused_kwargs = PretrainedConfig.get_config_dict(pretrained_model_name_or_path, **kwargs)
                                 ^^^^^^^^^^^^^^^^^^^^^^^^^^^^^^^^^^^^^^^^^^^^^^^^^^^^^^^^^^^^^^^^^^^^^^^^^
  File "/home/jmcgrath/miniconda3/envs/ai-test-py312/lib/python3.12/site-packages/transformers/configuration_utils.py", line 608, in get_config_dict
    config_dict, kwargs = cls._get_config_dict(pretrained_model_name_or_path, **kwargs)
                          ^^^^^^^^^^^^^^^^^^^^^^^^^^^^^^^^^^^^^^^^^^^^^^^^^^^^^^^^^^^^^
  File "/home/jmcgrath/miniconda3/envs/ai-test-py312/lib/python3.12/site-packages/transformers/configuration_utils.py", line 667, in _get_config_dict
    resolved_config_file = cached_file(
                           ^^^^^^^^^^^^
  File "/home/jmcgrath/miniconda3/envs/ai-test-py312/lib/python3.12/site-packages/transformers/utils/hub.py", line 312, in cached_file
    file = cached_files(path_or_repo_id=path_or_repo_id, filenames=[filename], **kwargs)
           ^^^^^^^^^^^^^^^^^^^^^^^^^^^^^^^^^^^^^^^^^^^^^^^^^^^^^^^^^^^^^^^^^^^^^^^^^^^^^
  File "/home/jmcgrath/miniconda3/envs/ai-test-py312/lib/python3.12/site-packages/transformers/utils/hub.py", line 533, in cached_files
    raise OSError(
OSError: You are trying to access a gated repo.
Make sure to have access to it at https://huggingface.co/meta-llama/Llama-3.3-70B-Instruct.
401 Client Error. (Request ID: Root=1-687245c2-32518b280d6d60a15e8d0bac;03c95e9c-8acd-4b2a-8c6d-6a3639ee9671)

Cannot access gated repo for url https://huggingface.co/meta-llama/Llama-3.3-70B-Instruct/resolve/main/config.json.
Access to model meta-llama/Llama-3.3-70B-Instruct is restricted. You must have access to it and be authenticated to access it. Please log in.
